<?xml version="1.0" encoding="utf-8"?>
<!-- This URDF was automatically created by SolidWorks to URDF Exporter! Originally created by Stephen Brawner (brawner@gmail.com) 
     Commit Version: 1.6.0-4-g7f85cfe  Build Version: 1.6.7995.38578
     For more information, please see http://wiki.ros.org/sw_urdf_exporter -->
<robot name="puma_model_camera" xmlns:xacro="http://ros.org/wiki/xacro">
  <xacro:include filename="$(find puma_model_camera)/urdf/puma_model.gazebo.xacro"/>
  
  <xacro:arg name="use_nominal_extrinsics" default="true"/>
  <xacro:arg name="add_plug" default="false" />
  <xacro:arg name="name" default="camera" />
  <xacro:arg name="topics_ns" default="camera" />
  <xacro:arg name="publish_pointcloud" default="true" />
  <xacro:include filename="$(find puma_model_camera)/urdf/d455.urdf.xacro" />

  <link
    name="base_link">
    <inertial>
      <origin
        xyz="-0.559904066756664 2.52439420520001E-07 0.369470453921975"
        rpy="0 0 0" />
      <mass
        value="154.381267641272" />
      <inertia
        ixx="3.8643546710344"
        ixy="-9.50231640664163E-07"
        ixz="1.15363830622366"
        iyy="22.232099682778"
        iyz="9.01311880646326E-06"
        izz="22.6507305397505" />
    </inertial>
    <visual>
      <origin
        xyz="0 0 0"
        rpy="0 0 0" />
      <geometry>
        <mesh
          filename="package://puma_model_camera/meshes/v2/base_link.STL" />
      </geometry>
      <material
        name="">
        <color
          rgba="0.988235294117647 0.737254901960784 0.517647058823529 1" />
      </material>
    </visual>
    <collision>
      <origin
        xyz="0 0 0"
        rpy="0 0 0" />
      <geometry>
        <mesh
          filename="package://puma_model_camera/meshes/v2/base_link.STL" />
      </geometry>
    </collision>
  </link>
  <link
    name="dir_right_link">
    <inertial>
      <origin
        xyz="-2.22044604925031E-16 -0.0294777193153578 1.11022302462516E-16"
        rpy="0 0 0" />
      <mass
        value="0.214607285846125" />
      <inertia
        ixx="0.000161787233745492"
        ixy="-1.24830140229751E-20"
        ixz="-1.78299811249943E-21"
        iyy="0.000212842937751498"
        iyz="1.23372093603248E-20"
        izz="0.000169651482672632" />
    </inertial>
    <visual>
      <origin
        xyz="0 0 0"
        rpy="0 0 0" />
      <geometry>
        <mesh
          filename="package://puma_model_camera/meshes/v2/dir_right_link.STL" />
      </geometry>
      <material
        name="">
        <color
          rgba="0.823529411764706 0.823529411764706 0.823529411764706 1" />
      </material>
    </visual>
    <collision>
      <origin
        xyz="0 0 0"
        rpy="0 0 0" />
      <geometry>
        <mesh
          filename="package://puma_model_camera/meshes/v2/dir_right_link.STL" />
      </geometry>
    </collision>
  </link>
  <joint
    name="dir_right_joint"
    type="continuous">
    <origin
      xyz="0 -0.337 0.265"
      rpy="0 0 0" />
    <parent
      link="base_link" />
    <child
      link="dir_right_link" />
    <axis
      xyz="0 0 1" />
  </joint>
  <link
    name="wheel_right_front_link">
    <inertial>
      <origin
        xyz="0 1.11022302462516E-16 0.07"
        rpy="0 0 0" />
      <mass
        value="33.8332405777372" />
      <inertia
        ixx="0.663166940004142"
        ixy="1.74598601904134E-32"
        ixz="4.51486827425246E-17"
        iyy="0.663166940004142"
        iyz="1.07735398960113E-17"
        izz="1.19194782788173" />
    </inertial>
    <visual>
      <origin
        xyz="0 0 0"
        rpy="0 0 0" />
      <geometry>
        <mesh
          filename="package://puma_model_camera/meshes/v2/wheel_right_front_link.STL" />
      </geometry>
      <material
        name="">
        <color
          rgba="1 0.752941176470588 0.752941176470588 1" />
      </material>
    </visual>
    <collision>
      <origin
        xyz="0 0 0"
        rpy="0 0 0" />
      <geometry>
        <mesh
          filename="package://puma_model_camera/meshes/v2/wheel_right_front_link.STL" />
      </geometry>
    </collision>
  </link>
  <joint
    name="wheel_right_front_joint"
    type="continuous">
    <origin
      xyz="0 -0.0480000000000001 0"
      rpy="1.5707963267949 0 0" />
    <parent
      link="dir_right_link" />
    <child
      link="wheel_right_front_link" />
    <axis
      xyz="0 0 -1" />
    <dynamics
      friction="1" />
  </joint>
  <link
    name="dir_left_link">
    <inertial>
      <origin
        xyz="0 0.0294777193153578 1.11022302462516E-16"
        rpy="0 0 0" />
      <mass
        value="0.214607285846125" />
      <inertia
        ixx="0.000161787233745492"
        ixy="1.23353249005569E-21"
        ixz="-2.86590106719918E-21"
        iyy="0.000212842937751498"
        iyz="2.66850804551272E-20"
        izz="0.000169651482672632" />
    </inertial>
    <visual>
      <origin
        xyz="0 0 0"
        rpy="0 0 0" />
      <geometry>
        <mesh
          filename="package://puma_model_camera/meshes/v2/dir_left_link.STL" />
      </geometry>
      <material
        name="">
        <color
          rgba="0.823529411764706 0.823529411764706 0.823529411764706 1" />
      </material>
    </visual>
    <collision>
      <origin
        xyz="0 0 0"
        rpy="0 0 0" />
      <geometry>
        <mesh
          filename="package://puma_model_camera/meshes/v2/dir_left_link.STL" />
      </geometry>
    </collision>
  </link>
  <joint
    name="dir_left_joint"
    type="continuous">
    <origin
      xyz="0 0.337 0.265"
      rpy="0 0 0" />
    <parent
      link="base_link" />
    <child
      link="dir_left_link" />
    <axis
      xyz="0 0 1" />
  </joint>
  <link
    name="wheel_left_front_link">
    <inertial>
      <origin
        xyz="0 0 0.0699999999999999"
        rpy="0 0 0" />
      <mass
        value="33.8332405777372" />
      <inertia
        ixx="0.663166940004142"
        ixy="3.62902943280336E-32"
        ixz="-3.47625364951278E-17"
        iyy="0.663166940004142"
        iyz="1.01566182105979E-18"
        izz="1.19194782788173" />
    </inertial>
    <visual>
      <origin
        xyz="0 0 0"
        rpy="0 0 0" />
      <geometry>
        <mesh
          filename="package://puma_model_camera/meshes/v2/wheel_left_front_link.STL" />
      </geometry>
      <material
        name="">
        <color
          rgba="1 0.752941176470588 0.752941176470588 1" />
      </material>
    </visual>
    <collision>
      <origin
        xyz="0 0 0"
        rpy="0 0 0" />
      <geometry>
        <mesh
          filename="package://puma_model_camera/meshes/v2/wheel_left_front_link.STL" />
      </geometry>
    </collision>
  </link>
  <joint
    name="wheel_left_front_joint"
    type="continuous">
    <origin
      xyz="0 0.048 0"
      rpy="1.5707963267949 0 -3.14159265358979" />
    <parent
      link="dir_left_link" />
    <child
      link="wheel_left_front_link" />
    <axis
      xyz="0 0 -1" />
    <dynamics
      friction="1" />
  </joint>
  <link
    name="wheel_right_back_link">
    <inertial>
      <origin
        xyz="0 -1.11022302462516E-16 0.1"
        rpy="0 0 0" />
      <mass
        value="42.8421975932662" />
      <inertia
        ixx="0.843504879614984"
        ixy="-2.17897005442215E-32"
        ixz="6.01287397790473E-17"
        iyy="0.843504879614984"
        iyz="-2.51058847467066E-16"
        izz="1.34196583325215" />
    </inertial>
    <visual>
      <origin
        xyz="0 0 0"
        rpy="0 0 0" />
      <geometry>
        <mesh
          filename="package://puma_model_camera/meshes/v2/wheel_right_back_link.STL" />
      </geometry>
      <material
        name="">
        <color
          rgba="0.666666666666667 0.666666666666667 0.666666666666667 1" />
      </material>
    </visual>
    <collision>
      <origin
        xyz="0 0 0"
        rpy="0 0 0" />
      <geometry>
        <mesh
          filename="package://puma_model_camera/meshes/v2/wheel_right_back_link.STL" />
      </geometry>
    </collision>
  </link>
  <joint
    name="wheel_right_back_joint"
    type="continuous">
    <origin
      xyz="-1.15000189278629 -0.275 0.25"
      rpy="1.5707963267949 0 0" />
    <parent
      link="base_link" />
    <child
      link="wheel_right_back_link" />
    <axis
      xyz="0 0 -1" />
    <dynamics
      friction="1" />
  </joint>
  <link
    name="wheel_left_back_link">
    <inertial>
      <origin
        xyz="1.11022302462516E-16 1.11022302462516E-16 0.1"
        rpy="0 0 0" />
      <mass
        value="42.8421975932662" />
      <inertia
        ixx="0.843504879614984"
        ixy="-4.06685460585995E-33"
        ixz="-3.69567293190446E-18"
        iyy="0.843504879614984"
        iyz="1.64612942139347E-17"
        izz="1.34196583325215" />
    </inertial>
    <visual>
      <origin
        xyz="0 0 0"
        rpy="0 0 0" />
      <geometry>
        <mesh
          filename="package://puma_model_camera/meshes/v2/wheel_left_back_link.STL" />
      </geometry>
      <material
        name="">
        <color
          rgba="0.666666666666667 0.666666666666667 0.666666666666667 1" />
      </material>
    </visual>
    <collision>
      <origin
        xyz="0 0 0"
        rpy="0 0 0" />
      <geometry>
        <mesh
          filename="package://puma_model_camera/meshes/v2/wheel_left_back_link.STL" />
      </geometry>
    </collision>
  </link>
  <joint
    name="wheel_left_back_joint"
    type="continuous">
    <origin
      xyz="-1.15000189278629 0.275 0.25"
      rpy="-1.5707963267949 0 0" />
    <parent
      link="base_link" />
    <child
      link="wheel_left_back_link" />
    <axis
      xyz="0 0 -1" />
    <dynamics
      friction="1" />
  </joint>
  <link
    name="base_component_link">
    <inertial>
      <origin
        xyz="-1.38777878078145E-17 -1.38777878078145E-17 0"
        rpy="0 0 0" />
      <mass
        value="26.928" />
      <inertia
        ixx="0.399432"
        ixy="-5.82648744066697E-18"
        ixz="-6.57606322748783E-34"
        iyy="0.368016"
        iyz="1.74696983473478E-33"
        izz="0.5502288" />
    </inertial>
    <visual>
      <origin
        xyz="0 0 0"
        rpy="0 0 0" />
      <geometry>
        <mesh
          filename="package://puma_model_camera/meshes/v2/base_component_link.STL" />
      </geometry>
      <material
        name="">
        <color
          rgba="1 0.752941176470588 1 1" />
      </material>
    </visual>
    <collision>
      <origin
        xyz="0 0 0"
        rpy="0 0 0" />
      <geometry>
        <mesh
          filename="package://puma_model_camera/meshes/v2/base_component_link.STL" />
      </geometry>
    </collision>
  </link>
  <joint
    name="base_component_joint"
    type="fixed">
    <origin
      xyz="-0.450001892786288 0 0.63"
      rpy="0 0 0" />
    <parent
      link="base_link" />
    <child
      link="base_component_link" />
    <axis
      xyz="0 0 0" />
  </joint>
  <link
    name="gps_link">
    <inertial>
      <origin
        xyz="0 -1.38777878078145E-17 -0.01"
        rpy="0 0 0" />
      <mass
        value="0.1" />
      <inertia
        ixx="8.66666666666668E-05"
        ixy="-6.77626357802914E-24"
        ixz="1.44560289664734E-22"
        iyy="2.41666666666667E-05"
        iyz="-2.17743936307504E-22"
        izz="0.000104166666666667" />
    </inertial>
    <visual>
      <origin
        xyz="0 0 0"
        rpy="0 0 0" />
      <geometry>
        <mesh
          filename="package://puma_model_camera/meshes/v2/gps_link.STL" />
      </geometry>
      <material
        name="">
        <color
          rgba="0.623529411764706 1 0.76078431372549 1" />
      </material>
    </visual>
    <collision>
      <origin
        xyz="0 0 0"
        rpy="0 0 0" />
      <geometry>
        <mesh
          filename="package://puma_model_camera/meshes/v2/gps_link.STL" />
      </geometry>
    </collision>
  </link>
  <joint
    name="gps_joint"
    type="fixed">
    <origin
      xyz="-0.305001892786288 0 0.76"
      rpy="0 0 0" />
    <parent
      link="base_link" />
    <child
      link="gps_link" />
    <axis
      xyz="0 0 0" />
  </joint>
  <link
    name="imu_link">
    <inertial>
      <origin
        xyz="5.08055300385557E-07 -0.000195569944066151 -0.0121628383871961"
        rpy="0 0 0" />
      <mass
        value="0.0106550387325199" />
      <inertia
        ixx="1.16705248203446E-06"
        ixy="2.03256158405584E-11"
        ixz="2.11642113815375E-12"
        iyy="2.20541869708662E-06"
        iyz="-8.14691556822213E-10"
        izz="2.78315231388432E-06" />
    </inertial>
    <visual>
      <origin
        xyz="0 0 0"
        rpy="0 0 0" />
      <geometry>
        <mesh
          filename="package://puma_model_camera/meshes/v2/imu_link.STL" />
      </geometry>
      <material
        name="">
        <color
          rgba="0.792156862745098 0.819607843137255 0.933333333333333 1" />
      </material>
    </visual>
    <collision>
      <origin
        xyz="0 0 0"
        rpy="0 0 0" />
      <geometry>
        <mesh
          filename="package://puma_model_camera/meshes/v2/imu_link.STL" />
      </geometry>
    </collision>
  </link>
  <joint
    name="imu_joint"
    type="fixed">
    <origin
      xyz="-0.363001892786288 0.00300000000000007 0.761"
      rpy="0 0 0" />
    <parent
      link="base_link" />
    <child
      link="imu_link" />
    <axis
      xyz="0 0 0" />
  </joint>
  <link
    name="camara_link">
    <inertial>
      <origin
        xyz="-0.00149999999999995 2.77555756156289E-17 -1.11022302462516E-16"
        rpy="0 0 0" />
      <mass
        value="0.0105304777960769" />
      <inertia
        ixx="1.36186520257664E-05"
        ixy="-2.34298407531536E-24"
        ixz="-5.96948675392447E-24"
        iyy="7.24303978619533E-07"
        iyz="8.97261282281197E-22"
        izz="1.2910143763841E-05" />
    </inertial>
    <visual>
      <origin
        xyz="0 0 0"
        rpy="0 0 0" />
      <geometry>
        <mesh
          filename="package://puma_model_camera/meshes/v2/camara_link.STL" />
      </geometry>
      <material
        name="">
        <color
          rgba="0.792156862745098 0.819607843137255 0.933333333333333 1" />
      </material>
    </visual>
    <collision>
      <origin
        xyz="0 0 0"
        rpy="0 0 0" />
      <geometry>
        <mesh
          filename="package://puma_model_camera/meshes/v2/camara_link.STL" />
      </geometry>
    </collision>
  </link>
  <joint
    name="camara_joint"
    type="fixed">
    <origin
      xyz="0.0529981072137121 0 0.36"
      rpy="0 0 0" />
    <parent
      link="base_link" />
    <child
      link="camara_link" />
    <axis
      xyz="0 0 0" />
  </joint>
  

  <xacro:sensor_d455 parent="camara_link" use_nominal_extrinsics="$(arg use_nominal_extrinsics)" add_plug="$(arg add_plug)"  name="$(arg name)" topics_ns="$(arg topics_ns)" publish_pointcloud="$(arg publish_pointcloud)">
    <origin xyz="0 0 0" rpy="0 0 0"/>
  </xacro:sensor_d455>

</robot>